<robot
  name="elfin15" xmlns:xacro="http://www.ros.org/wiki/xacro">
  
  <xacro:include filename="$(find elfin_description)/urdf/materials.xacro" />
  
  <xacro:include filename="$(find elfin_description)/urdf/elfin_robot.gazebo" />
  
  <xacro:include filename="$(find elfin_description)/urdf/elfin_transmission.xacro" />

  <link name="world" />

  <joint name="world_base" type="fixed">
    <origin
      xyz="0 0 0"
      rpy="0 0 0" />
    <parent
      link="world" />
    <child
      link="elfin_base_link" />
  </joint>

  <link name="elfin_base_link" />

  <joint name="elfin_base_joint" type="fixed">
    <origin
      xyz="0 0 0"
      rpy="0 0 0" />
    <parent
      link="elfin_base_link" />
    <child
      link="base_link" />
  </joint>

  <link
    name="base_link">
    <inertial>
      <origin
        xyz="-0.000695002623445946 -5.07508519484099E-06 0.0375658828060339"
        rpy="0 0 0" />
      <mass
        value="2.71888716466908" />
      <inertia
        ixx="0.00938317508875725"
        ixy="-3.60387611495622E-08"
        ixz="-6.88676148720587E-05"
        iyy="0.00898832759881519"
        iyz="-1.99352155737403E-07"
        izz="0.0157105653615728" />
    </inertial>
    <visual>
      <origin
        xyz="0 0 0"
        rpy="0 0 0" />
      <geometry>
        <mesh
          filename="package://elfin_description/meshes/elfin15_F/base_link.STL" />
      </geometry>
      <material
        name="">
        <color
          rgba="0.866666666666667 0.866666666666667 0.890196078431372 1" />
      </material>
    </visual>
    <collision>
      <origin
        xyz="0 0 0"
        rpy="0 0 0" />
      <geometry>
        <mesh
          filename="package://elfin_description/meshes/elfin15_F/base_link.STL" />
      </geometry>
    </collision>
  </link>
  <link
    name="elfin_link1">
    <inertial>
      <origin
        xyz="8.07683021386315E-06 -0.0035773925820559 0.146117252792634"
        rpy="0 0 0" />
      <mass
        value="9.69439879854905" />
      <inertia
        ixx="0.0873560745698383"
        ixy="7.48773843082023E-06"
        ixz="-1.01202228048275E-05"
        iyy="0.0784436265757321"
        iyz="0.0020149616199151"
        izz="0.0586857551015982" />
    </inertial>
    <visual>
      <origin
        xyz="0 0 0"
        rpy="0 0 0" />
      <geometry>
        <mesh
          filename="package://elfin_description/meshes/elfin15_F/elfin_link1.STL" />
      </geometry>
      <material
        name="">
        <color
          rgba="1 1 1 1" />
      </material>
    </visual>
    <collision>
      <origin
        xyz="0 0 0"
        rpy="0 0 0" />
      <geometry>
        <mesh
          filename="package://elfin_description/meshes/elfin15_F/elfin_link1.STL" />
      </geometry>
    </collision>
  </link>
  <joint
    name="elfin_joint1"
    type="revolute">
    <origin
      xyz="0 0 0.08"
      rpy="0 0 0" />
    <parent
      link="base_link" />
    <child
      link="elfin_link1" />
    <axis
      xyz="0 0 1" />
    <limit
      lower="-3.14"
      upper="3.14"
      effort="420"
      velocity="1.57" />
  </joint>
  <link
    name="elfin_link2">
    <inertial>
      <origin
        xyz="2.00668503935044E-05 -0.0350913888576602 0.29208552291378"
        rpy="0 0 0" />
      <mass
        value="9.54892004428153" />
      <inertia
        ixx="0.589306179672266"
        ixy="4.62108054755441E-06"
        ixz="-5.92121709739712E-05"
        iyy="0.59606406844587"
        iyz="-0.0314540755137635"
        izz="0.0224322625270061" />
    </inertial>
    <visual>
      <origin
        xyz="0 0 0"
        rpy="0 0 0" />
      <geometry>
        <mesh
          filename="package://elfin_description/meshes/elfin15_F/elfin_link2.STL" />
      </geometry>
      <material
        name="">
        <color
          rgba="0.890196078431372 0.890196078431372 0.913725490196078 1" />
      </material>
    </visual>
    <collision>
      <origin
        xyz="0 0 0"
        rpy="0 0 0" />
      <geometry>
        <mesh
          filename="package://elfin_description/meshes/elfin15_F/elfin_link2.STL" />
      </geometry>
    </collision>
  </link>
  <joint
    name="elfin_joint2"
    type="revolute">
    <origin
      xyz="0 -0.11895 0.182"
      rpy="0 0 0" />
    <parent
      link="elfin_link1" />
    <child
      link="elfin_link2" />
    <axis
      xyz="0 -1 0" />
    <limit
      lower="-2.35"
      upper="2.35"
      effort="420"
      velocity="1.57" />
  </joint>
  <link
    name="elfin_link3">
    <inertial>
      <origin
        xyz="-3.35410138302954E-06 0.0807007389842829 0.0361017927579714"
        rpy="0 0 0" />
      <mass
        value="2.9169641646369" />
      <inertia
        ixx="0.0135718271521769"
        ixy="-2.93064412428029E-07"
        ixz="4.8594264368378E-07"
        iyy="0.0118099812788293"
        iyz="-0.000536922283164078"
        izz="0.00742983650345206" />
    </inertial>
    <visual>
      <origin
        xyz="0 0 0"
        rpy="0 0 0" />
      <geometry>
        <mesh
          filename="package://elfin_description/meshes/elfin15_F/elfin_link3.STL" />
      </geometry>
      <material
        name="">
        <color
          rgba="1 1 1 1" />
      </material>
    </visual>
    <collision>
      <origin
        xyz="0 0 0"
        rpy="0 0 0" />
      <geometry>
        <mesh
          filename="package://elfin_description/meshes/elfin15_F/elfin_link3.STL" />
      </geometry>
    </collision>
  </link>
  <joint
    name="elfin_joint3"
    type="revolute">
    <origin
      xyz="0 0.03388 0.73"
      rpy="0 0 0" />
    <parent
      link="elfin_link2" />
    <child
      link="elfin_link3" />
    <axis
      xyz="0 1 0" />
    <limit
      lower="-2.61"
      upper="2.61"
      effort="200"
      velocity="1.57" />
  </joint>
  <link
    name="elfin_link4">
    <inertial>
      <origin
        xyz="3.96870930380675E-05 -0.0650155014813431 0.173832877361676"
        rpy="0 0 0" />
      <mass
        value="2.82013626298568" />
      <inertia
        ixx="0.0599767847611795"
        ixy="3.79703423156232E-06"
        ixz="-1.98457784458686E-05"
        iyy="0.0558250152691264"
        iyz="0.0126917028887549"
        izz="0.00791935431280652" />
    </inertial>
    <visual>
      <origin
        xyz="0 0 0"
        rpy="0 0 0" />
      <geometry>
        <mesh
          filename="package://elfin_description/meshes/elfin15_F/elfin_link4.STL" />
      </geometry>
      <material
        name="">
        <color
          rgba="1 1 1 1" />
      </material>
    </visual>
    <collision>
      <origin
        xyz="0 0 0"
        rpy="0 0 0" />
      <geometry>
        <mesh
          filename="package://elfin_description/meshes/elfin15_F/elfin_link4.STL" />
      </geometry>
    </collision>
  </link>
  <joint
    name="elfin_joint4"
    type="revolute">
    <origin
      xyz="0 0.08507 0.147"
      rpy="0 0 0" />
    <parent
      link="elfin_link3" />
    <child
      link="elfin_link4" />
    <axis
      xyz="0 0 1" />
    <limit
      lower="-3.14"
      upper="3.14"
      effort="200"
      velocity="1.57" />
  </joint>
  <link
    name="elfin_link5">
    <inertial>
      <origin
        xyz="7.12907192415623E-06 0.0685097120449843 0.0250239802320473"
        rpy="0 0 0" />
      <mass
        value="1.25663358547766" />
      <inertia
        ixx="0.00349953854194773"
        ixy="-4.77573905026001E-07"
        ixz="-2.77272767775186E-07"
        iyy="0.00273055902205603"
        iyz="-9.97691077673872E-05"
        izz="0.00202572610862977" />
    </inertial>
    <visual>
      <origin
        xyz="0 0 0"
        rpy="0 0 0" />
      <geometry>
        <mesh
          filename="package://elfin_description/meshes/elfin15_F/elfin_link5.STL" />
      </geometry>
      <material
        name="">
        <color
          rgba="0.890196078431372 0.890196078431372 0.913725490196078 1" />
      </material>
    </visual>
    <collision>
      <origin
        xyz="0 0 0"
        rpy="0 0 0" />
      <geometry>
        <mesh
          filename="package://elfin_description/meshes/elfin15_F/elfin_link5.STL" />
      </geometry>
    </collision>
  </link>
  <joint
    name="elfin_joint5"
    type="revolute">
    <origin
      xyz="0 -0.071 0.423"
      rpy="0 0 0" />
    <parent
      link="elfin_link4" />
    <child
      link="elfin_link5" />
    <axis
      xyz="0 1 0" />
    <limit
      lower="-2.56"
      upper="2.56"
      effort="69"
      velocity="1.57" />
  </joint>
  <link
    name="elfin_link6">
    <inertial>
      <origin
        xyz="0.000340707984155859 -8.81908556493069E-05 0.0297965916937253"
        rpy="0 0 0" />
      <mass
        value="0.347759307077889" />
      <inertia
        ixx="0.000251824752714629"
        ixy="3.78375113977756E-08"
        ixz="2.3688911249132E-07"
        iyy="0.000252538114035222"
        iyz="-2.61458838436258E-08"
        izz="0.000309218903006093" />
    </inertial>
    <visual>
      <origin
        xyz="0 0 0"
        rpy="0 0 0" />
      <geometry>
        <mesh
          filename="package://elfin_description/meshes/elfin15_F/elfin_link6.STL" />
      </geometry>
      <material
        name="">
        <color
          rgba="0.792156862745098 0.819607843137255 0.933333333333333 1" />
      </material>
    </visual>
    <collision>
      <origin
        xyz="0 0 0"
        rpy="0 0 0" />
      <geometry>
        <mesh
          filename="package://elfin_description/meshes/elfin15_F/elfin_link6.STL" />
      </geometry>
    </collision>
  </link>
  <joint
    name="elfin_joint6"
    type="revolute">
    <origin
      xyz="0 0.071 0.111"
      rpy="0 0 0" />
    <parent
      link="elfin_link5" />
    <child
      link="elfin_link6" />
    <axis
      xyz="0 0 1" />
    <limit
      lower="-3.14"
      upper="3.14"
      effort="69"
      velocity="1.57" />
  </joint>

  <link name="elfin_end_link" />

  <joint
    name="elfin_end_joint"
    type="fixed">
    <origin
      xyz="0 0 0.0625"
      rpy="0 0 0" />
    <parent
      link="elfin_link6" />
    <child
      link="elfin_end_link" />
    <axis
      xyz="0 0 0" />
  </joint>
  <link name="elfin_dummy_gripper"/>
  
  <joint name="elfin_dummy_joint" type="fixed">
    <origin
      xyz="0 0.109 0"
      rpy="-1.5708 1.5708 0" />
    <parent
      link="elfin_link6" />
    <child
      link="elfin_dummy_gripper" />
  </joint>

</robot>
